Traceback (most recent call last):
  File "/Users/kimnielsen/opt/anaconda3/lib/python3.9/site-packages/jupyter_cache/executors/utils.py", line 58, in single_nb_execution
    executenb(
  File "/Users/kimnielsen/opt/anaconda3/lib/python3.9/site-packages/nbclient/client.py", line 1204, in execute
    return NotebookClient(nb=nb, resources=resources, km=km, **kwargs).execute()
  File "/Users/kimnielsen/opt/anaconda3/lib/python3.9/site-packages/nbclient/util.py", line 84, in wrapped
    return just_run(coro(*args, **kwargs))
  File "/Users/kimnielsen/opt/anaconda3/lib/python3.9/site-packages/nbclient/util.py", line 62, in just_run
    return loop.run_until_complete(coro)
  File "/Users/kimnielsen/opt/anaconda3/lib/python3.9/asyncio/base_events.py", line 647, in run_until_complete
    return future.result()
  File "/Users/kimnielsen/opt/anaconda3/lib/python3.9/site-packages/nbclient/client.py", line 663, in async_execute
    await self.async_execute_cell(
  File "/Users/kimnielsen/opt/anaconda3/lib/python3.9/site-packages/nbclient/client.py", line 965, in async_execute_cell
    await self._check_raise_for_error(cell, cell_index, exec_reply)
  File "/Users/kimnielsen/opt/anaconda3/lib/python3.9/site-packages/nbclient/client.py", line 862, in _check_raise_for_error
    raise CellExecutionError.from_cell_and_msg(cell, exec_reply_content)
nbclient.exceptions.CellExecutionError: An error occurred while executing the following cell:
------------------
%reset -f

import numpy as np

c = 2.9979e8
u = 0.950*c

# Part 1
dt = 7.05e-6  #found in example
dx = u*dt  #proper length
print('Distance traveled according to earthbound observer: '+str(dx)+' m')

# Part 2
dt_prime = 2.20e-6  #given in example
dx_prime = u*dt0
print('Distance traveled according to muon observer: '+str(dx_prime)+' m')

# Part 3
gamma = dx/dx_prime
print('Gamma based on length contraction: '+str(gamma))

------------------

[0;31m---------------------------------------------------------------------------[0m
[0;31mNameError[0m                                 Traceback (most recent call last)
Input [0;32mIn [12][0m, in [0;36m<cell line: 15>[0;34m()[0m
[1;32m     13[0m [38;5;66;03m# Part 2[39;00m
[1;32m     14[0m dt_prime [38;5;241m=[39m [38;5;241m2.20e-6[39m  [38;5;66;03m#given in example[39;00m
[0;32m---> 15[0m dx_prime [38;5;241m=[39m u[38;5;241m*[39m[43mdt0[49m
[1;32m     16[0m [38;5;28mprint[39m([38;5;124m'[39m[38;5;124mDistance traveled according to muon observer: [39m[38;5;124m'[39m[38;5;241m+[39m[38;5;28mstr[39m(dx_prime)[38;5;241m+[39m[38;5;124m'[39m[38;5;124m m[39m[38;5;124m'[39m)
[1;32m     18[0m [38;5;66;03m# Part 3[39;00m

[0;31mNameError[0m: name 'dt0' is not defined
NameError: name 'dt0' is not defined

